<?xml version="1.0"?>

<robot name="lwa4p" xmlns:xacro="http://www.ros.org/wiki/xacro"  >

  <!-- Include materials -->

  <material name="Schunk/LightGrey">
    <color rgba="0.7 0.7 0.7 1.0"/>
  </material>

  <material name="Schunk/DarkGrey">
    <color rgba="0.4 0.4 0.4 1.0"/>
  </material>

  <material name="Schunk/Black">
    <color rgba="0.0 0.0 0.0 1.0"/>
  </material>

  <material name="Schunk/DarkGolden">
    <color rgba="0.4 0.4 0.3 1.0"/>
  </material>

  <material name="Schunk/Blue">
    <color rgba="0.0 0.0 0.8 1.0"/>
  </material>

<!-- ///////////////////////////////////////////////////////////////////////////////////////////////////////////////////// -->
  <link name="world">
    <origin rpy="0 0 0" xyz="0 0 0"/>
  </link>


  <joint name="podest_joint" type="fixed">
    
    <parent link="world"/>
    <child link="podest_link"/>
  </joint>
  <link name="podest_link">

    <visual>
      <origin xyz="0 0 0" rpy="0 3.1416 0" />
      <geometry>
      <mesh filename="package://schunk_description/meshes/lwa4p/arm_base_link.stl" />
      </geometry>
    </visual>

    <collision>
      <origin xyz="0 0 0" rpy="0 3.1416 0" />
      <geometry>
      <mesh filename="package://schunk_description/meshes/lwa4p/arm_base_link.stl" />
      </geometry>
    </collision>
  </link>

  <joint name="base_joint" type="fixed">
    <origin xyz="0 0 0.10" rpy="0 0 0" />
    <parent link="podest_link"/>
    <child link="base_link"/>
  </joint>

  <link name="base_link">
    <origin rpy="0 0 0" xyz="0 0 0"/>
  </link>
  
  <!-- joint between arm_base_link and arm_1_link -->
  <joint name="arm_1_joint" type="revolute">
    <origin xyz="0 0 0" rpy="0 0 0" />
    <parent link="base_link"/>
    <child link="1_link"/>
    <axis xyz="0 0 1"/>
    <limit effort="370" velocity="1.26" lower="-2.967" upper="2.967"/>
    <!--safety_controller k_position="20" k_velocity="50" soft_lower_limit="-6.28 + 0.01" soft_upper_limit="6.28 - 0.01" /-->
  </joint>

  <link name="1_link">
    

    <inertial>
      <origin xyz="0 0 0" rpy="0 0 0" />
      <mass value="0.29364"/>
      <inertia ixx="0.01" ixy="0" ixz="0" iyy="0.01" iyz="0" izz="0.01" />
    </inertial>


    <visual>
      <origin xyz="0 0 0" rpy="0 0 0" />
      <geometry>
        <mesh filename="package://schunk_description/meshes/lwa4p/arm_1_link.stl" />
      </geometry>
      <material name="Schunk/Blue" />
    </visual>

    <collision>
      <origin xyz="0 0 0" rpy="0 0 0" />
      <geometry>
        <mesh filename="package://schunk_description/meshes/lwa4p/arm_1_link.stl" />
      </geometry>
    </collision>
  </link>

  <!-- joint between arm_1_link and arm_2_link -->
  <joint name="arm_2_joint" type="revolute">
    <origin xyz="0 0 0" rpy="1.5708 0 0"/>
    <parent link="1_link"/>
    <child link="2_link"/>
    <axis xyz="0 0 1"/>
    <limit effort="370" velocity="1.26" lower="-2.967" upper="2.967"/>
    <!--safety_controller k_position="20" k_velocity="50" soft_lower_limit="-2.09 + 0.01" soft_upper_limit="2.09 - 0.01" /-->
  </joint>

  <link name="2_link">
    

    <inertial>
      <origin xyz="0 0 0" rpy="0 0 0"/>
      <mass value="1.68311"/>
      <inertia ixx="0.03" ixy="0" ixz="0" iyy="0.03" iyz="0" izz="0.03" />
    </inertial>


    <visual>
      <origin xyz="0 0 0" rpy="0 0 0" />
      <geometry>
        <mesh filename="package://schunk_description/meshes/lwa4p/arm_2_link.stl" />
      </geometry>
      <material name="Schunk/LightGrey" />
    </visual>

    <collision>
      <origin xyz="0 0 0" rpy="0 0 0" />
      <geometry>
        <mesh filename="package://schunk_description/meshes/lwa4p/arm_2_link.stl" />
      </geometry>
    </collision>
  </link>

  <!-- joint between arm_2_link and arm_3_link -->
  <joint name="arm_3_joint" type="revolute">
    <origin xyz="0 0.350 0" rpy="0 3.14159 0"/>
    <parent link="2_link"/>
    <child link="3_link"/>
    <axis xyz="0 0 1"/>
    <limit effort="176" velocity="1.26" lower="-2.714" upper="2.714"/>
    <!--safety_controller k_position="20" k_velocity="25" soft_lower_limit="-6.28 + 0.01" soft_upper_limit="6.28 - 0.01" /-->
  </joint>

  <link name="3_link">
    

    <inertial>
      <origin xyz="0 0 0" rpy="0 0 0"/>
      <mass value="2.1"/>
      <inertia ixx="0.03" ixy="0" ixz="0" iyy="0.03" iyz="0" izz="0.03" />
    </inertial>


    <visual>
      <origin xyz="0 0 0" rpy="0 0 0" />
      <geometry>
        <mesh filename="package://schunk_description/meshes/lwa4p/arm_3_link.stl" />
      </geometry>
      <material name="Schunk/Blue" />
    </visual>

    <collision>
      <origin xyz="0 0 0" rpy="0 0 0" />
      <geometry>
        <mesh filename="package://schunk_description/meshes/lwa4p/arm_3_link.stl" />
      </geometry>
    </collision>
  </link>

  <!-- joint between arm_3_link and arm_4_link -->
  <joint name="arm_4_joint" type="revolute">
    <origin xyz="0 0 0" rpy="-1.5708 3.14159 0" />
    <parent link="3_link"/>
    <child link="4_link"/>
    <axis xyz="0 0 1" />
    <limit effort="176" velocity="1.26" lower="-2.967" upper="2.967"/>
    <!--safety_controller k_position="20" k_velocity="25" soft_lower_limit="-2.09 + 0.01" soft_upper_limit="2.09 - 0.01" /-->
  </joint>

  <link name="4_link">
    

    <inertial>
      <origin xyz="0 0 0" rpy="0 0 0"/>
      <mass value="1.68311"/>
      <inertia ixx="0.03" ixy="0" ixz="0" iyy="0.03" iyz="0" izz="0.03" />
    </inertial>


    <visual>
      <origin xyz="0 0 0" rpy="0 0 0" />
      <geometry>
        <mesh filename="package://schunk_description/meshes/lwa4p/arm_4_link.stl" />
      </geometry>
      <material name="Schunk/LightGrey" />
    </visual>

    <collision>
      <origin xyz="0 0 0" rpy="0 0 0" />
      <geometry>
        <mesh filename="package://schunk_description/meshes/lwa4p/arm_4_link.stl" />
      </geometry>
    </collision>
  </link>

  <!-- joint between arm_4_link and arm_5_link -->
  <joint name="arm_5_joint" type="revolute">
    <origin xyz="0 0.005263 0.305" rpy="1.5708 0 3.14159" />
    <parent link="4_link"/>
    <child link="5_link"/>
    <axis xyz="0 0 1" />
    <limit effort="41.6" velocity="1.26" lower="-2.967" upper="2.967" />
    <!--safety_controller k_position="20" k_velocity="25" soft_lower_limit="-6.28 + 0.01" soft_upper_limit="6.28 - 0.01" /-->
  </joint>

  <link name="5_link">
    

    <inertial>
      <origin xyz="0 0 0" rpy="0 0 0"/>
      <mass value="0.807"/>
      <inertia ixx="0.03" ixy="0" ixz="0" iyy="0.03" iyz="0" izz="0.03" />
    </inertial>


    <visual>
      <origin xyz="0 0 0" rpy="0 0 0" />
      <geometry>
        <mesh filename="package://schunk_description/meshes/lwa4p/arm_5_link.stl" />
      </geometry>
      <material name="Schunk/Blue" />
    </visual>

    <collision>
      <origin xyz="0 0 0" rpy="0 0 0" />
      <geometry>
        <mesh filename="package://schunk_description/meshes/lwa4p/arm_5_link.stl" />
      </geometry>
    </collision>
  </link>

  <!-- joint between arm_5_link and arm_6_link -->
  <joint name="arm_6_joint" type="revolute">
    <origin xyz="0 0 0" rpy="-1.5708 0 0" />
    <parent link="5_link"/>
    <child link="6_link"/>
    <axis xyz="0 0 1" />
    <limit effort="20.1" velocity="1.26" lower="-2.967" upper="2.967" />
    <!--safety_controller k_position="20" k_velocity="25" soft_lower_limit="-2.09 + 0.01" soft_upper_limit="2.09 - 0.01" /-->
  </joint>

  <link name="6_link">
    

    <inertial>
      <origin xyz="0 0 0" rpy="0 0 0"/>
      <mass value="0.819"/>
      <inertia ixx="0.01" ixy="0" ixz="0" iyy="0.01" iyz="0" izz="0.01" />
    </inertial>


    <visual>
      <origin xyz="0 0 0" rpy="0 0 0" />
      <geometry>
        <mesh filename="package://schunk_description/meshes/lwa4p/arm_6_link.stl" />
      </geometry>
      <material name="Schunk/LightGrey" />
    </visual>

    <collision>
      <origin xyz="0 0 0" rpy="0 0 0" />
      <geometry>
        <mesh filename="package://schunk_description/meshes/lwa4p/arm_6_link.stl" />
      </geometry>
    </collision>
  </link>

  <gazebo reference="0_link">
    <gravity>true</gravity>
    <self_collide>false</self_collide>
    <material value="Schunk/LightGrey" />
  </gazebo>

  <gazebo reference="1_link">
    <gravity>true</gravity>
    <self_collide>false</self_collide>
    <material value="Schunk/Blue" />
  </gazebo>

  <gazebo reference="2_link">
    <gravity>true</gravity>
    <self_collide>false</self_collide>
    <material value="Schunk/LightGrey" />
  </gazebo>

  <gazebo reference="3_link">
    <gravity>true</gravity>
    <self_collide>false</self_collide>
    <material value="Schunk/Blue" />
  </gazebo>

  <gazebo reference="4_link">
    <gravity>true</gravity>
    <self_collide>false</self_collide>
    <material value="Schunk/LightGrey" />
  </gazebo>

  <gazebo reference="5_link">
    <gravity>true</gravity>
    <self_collide>false</self_collide>
    <material value="Schunk/Blue" />
  </gazebo>

  <gazebo reference="6_link">
    <gravity>true</gravity>
    <self_collide>false</self_collide>
    <material value="Schunk/LightGrey" />
  </gazebo>







<!-- ///////////////////////////////////////////////////////////////////////////////////////////////////////////////////// -->
  <!-- Transmissions for ROS Control -->

  <transmission name="1_trans">
    <type>transmission_interface/SimpleTransmission</type>
    <joint name="arm_1_joint">
      <hardwareInterface>hardware_interface/PositionJointInterface</hardwareInterface>
      <hardwareInterface>VelocityJointInterface</hardwareInterface>
      <!--hardwareInterface>EffortJointInterface</hardwareInterface-->
    </joint>
    <actuator name="1_motor">
      <mechanicalReduction>1</mechanicalReduction>
    </actuator>
  </transmission>

  <transmission name="2_trans">
    <type>transmission_interface/SimpleTransmission</type>
    <joint name="arm_2_joint">
      <hardwareInterface>hardware_interface/PositionJointInterface</hardwareInterface>
      <hardwareInterface>VelocityJointInterface</hardwareInterface>
      <!--hardwareInterface>EffortJointInterface</hardwareInterface-->
    </joint>
    <actuator name="2_motor">
      <mechanicalReduction>1</mechanicalReduction>
    </actuator>
  </transmission>
  
  <transmission name="3_trans">
    <type>transmission_interface/SimpleTransmission</type>
    <joint name="arm_3_joint">
      <hardwareInterface>hardware_interface/PositionJointInterface</hardwareInterface>
      <hardwareInterface>VelocityJointInterface</hardwareInterface>
      <!--hardwareInterface>EffortJointInterface</hardwareInterface-->
    </joint>
    <actuator name="3_motor">
      <mechanicalReduction>1</mechanicalReduction>
    </actuator>
  </transmission>

  <transmission name="4_trans">
    <type>transmission_interface/SimpleTransmission</type>
    <joint name="arm_4_joint">
      <hardwareInterface>hardware_interface/PositionJointInterface</hardwareInterface>
      <hardwareInterface>VelocityJointInterface</hardwareInterface>
      <!--hardwareInterface>EffortJointInterface</hardwareInterface-->
    </joint>
    <actuator name="4_motor">
      <mechanicalReduction>1</mechanicalReduction>
    </actuator>
  </transmission>

  <transmission name="5_trans">
    <type>transmission_interface/SimpleTransmission</type>
    <joint name="arm_5_joint">
      <hardwareInterface>hardware_interface/PositionJointInterface</hardwareInterface>
      <hardwareInterface>VelocityJointInterface</hardwareInterface>
      <!--hardwareInterface>EffortJointInterface</hardwareInterface-->
    </joint>
    <actuator name="5_motor">
      <mechanicalReduction>1</mechanicalReduction>
    </actuator>
  </transmission>

  <transmission name="6_trans">
    <type>transmission_interface/SimpleTransmission</type>
    <joint name="arm_6_joint">
      <hardwareInterface>hardware_interface/PositionJointInterface</hardwareInterface>
      <hardwareInterface>VelocityJointInterface</hardwareInterface>
      <!--hardwareInterface>EffortJointInterface</hardwareInterface-->
    </joint>
    <actuator name="6_motor">
      <mechanicalReduction>1</mechanicalReduction>
    </actuator>
  </transmission>

	
 <!-- ros_control plugin -->
  <gazebo>
    <plugin name="gazebo_ros_control" filename="libgazebo_ros_control.so">
      <robotNamespace>lwa4p</robotNamespace>
      <!-- <filterJointsParam>joint_names</filterJointsParam> -->
      <!-- <robotSimType>gazebo_ros_control/DefaultRobotHWSim</robotSimType> -->
    </plugin>
  </gazebo>


</robot>
